Workbook

Sheet Read Me
A1: MMC Master Keyword Universe v2 (merged 2 Oct 2026: MMC strategy + 2 Oct keyword opportunity doc)
A3: What this is
A4: Every keyword MMC should check, by service, market and city. Search volume columns are EMPTY on purpose: no keyword tool was connected, and no number here is invented.
A6: How to fill volumes (cells to edit are shaded yellow on the Keywords sheet)
A7: 1. Google Keyword Planner (Google's own data, supports CITY targeting): Tools > Keyword Planner > Get search volume and forecasts. Paste the keywords for one 'GKP Location' at a time, set that location, language English, last 12 months. Paste the result into 'GKP Avg Monthly (range or number)'.
A8: Without active ad spend, GKP shows ranges such as 100 to 1K. With spend, it shows rounded averages. Neither is 'exact'; Google does not publish exact counts.
A9: 2. Ahrefs or Semrush (modelled estimates, COUNTRY level only): Keywords Explorer, country = IN / AE / US / CA / AU. Paste the keyword column (up to 10,000), export, paste Volume, KD and CPC into the yellow columns.
A10: City keywords such as 'meta ads agency in pune' are measured nationally in Ahrefs because the city is inside the query text. That is correct for this sheet.
A11: 3. The 'Opportunity Score' and the 'Summary' sheet calculate automatically once 'Ahrefs/Semrush Volume' is filled.
A13: Example of a filled row (format only, NOT real data)
A14: Keyword: meta ads agency in pune | GKP: 10 to 100 | Ahrefs Volume: 40 | KD: 12 | CPC (USD): 1.10
A16: Priority codes
... A24: Priority changes from v1: B2B lead generation and Education are P2 (P1 only once live paying clients with numbers exist). Quick commerce and Amazon stay P1 in the sheet but must be downgraded to P2 if no live account proof exists. London and Singapore are out of scope.

Sheet Keywords
A1: # | B1: Keyword | C1: Service | D1: Cluster | E1: Market | F1: GKP Location | G1: Intent | H1: Funnel stage | I1: Target page | J1: Priority | K1: Notes | L1: GKP Avg Monthly (range or number) | M1: Ahrefs/Semrush Volume | N1: KD | O1: CPC (USD) | P1: Opportunity Score | Q1: Count in totals
A2: 1 | B2: performance marketing agency in mumbai | C2: Performance marketing | D2: Service + city | E2: India | F2: Mumbai, Maharashtra, India | G2: Commercial | H2: Decision | I2: Hub (national) / city section | J2: 1 | P2: =IF(M2="","",ROUND(M2*IFERROR(INDEX(Weights!$B$2:$B$4,MATCH(G2,Weights!$A$2:$A$4,0)),0)*IFERROR(INDEX(Weights!$B$7:$B$11,MATCH(E2,Weights!$A$7:$A$11,0)),0)*IFERROR(INDEX(Weights!$B$14:$B$17,MATCH(TEXT(J2,"0"),Weights!$A$14:$A$17,0)),0)/(1+N(N2)/50),1)) | Q2: Y
A3: 2 | B3: digital marketing agency for ecommerce in mumbai | C3: Performance marketing | D3: Service + city | E3: India | F3: Mumbai, Maharashtra, India | G3: Commercial | H3: Decision | I3: Hub (national) | J3: 1 | P3: =IF(M3="","",ROUND(M3*IFERROR(INDEX(Weights!$B$2:$B$4,MATCH(G3,Weights!$A$2:$A$4,0)),0)*IFERROR(INDEX(Weights!$B$7:$B$11,MATCH(E3,Weights!$A$7:$A$11,0)),0)*IFERROR(INDEX(Weights!$B$14:$B$17,MATCH(TEXT(J3,"0"),Weights!$A$14:$A$17,0)),0)/(1+N(N3)/50),1)) | Q3: Y
A4: 3 | B4: d2c marketing agency in mumbai | C4: Performance marketing | D4: Service + city | E4: India | F4: Mumbai, Maharashtra, India | G4: Commercial | H4: Decision | I4: Hub (national) | J4: 1 | P4: =IF(M4="","",ROUND(M4*IFERROR(INDEX(Weights!$B$2:$B$4,MATCH(G4,Weights!$A$2:$A$4,0)),0)*IFERROR(INDEX(Weights!$B$7:$B$11,MATCH(E4,Weights!$A$7:$A$11,0)),0)*IFERROR(INDEX(Weights!$B$14:$B$17,MATCH(TEXT(J4,"0"),Weights!$A$14:$A$17,0)),0)/(1+N(N4)/50),1)) | Q4: Y
A5: 4 | B5: facebook ads agency in mumbai | C5: Meta Ads | D5: Service + city | E5: India | F5: Mumbai, Maharashtra, India | G5: Commercial | H5: Decision | I5: Meta Ads spoke | J5: 1 | P5: =IF(M5="","",ROUND(M5*IFERROR(INDEX(Weights!$B$2:$B$4,MATCH(G5,Weights!$A$2:$A$4,0)),0)*IFERROR(INDEX(Weights!$B$7:$B$11,MATCH(E5,Weights!$A$7:$A$11,0)),0)*IFERROR(INDEX(Weights!$B$14:$B$17,MATCH(TEXT(J5,"0"),Weights!$A$14:$A$17,0)),0)/(1+N(N5)/50),1)) | Q5: Y
A6: 5 | B6: meta ads agency in mumbai | C6: Meta Ads | D6: Service + city | E6: India | F6: Mumbai, Maharashtra, India | G6: Commercial | H6: Decision | I6: Meta Ads spoke | J6: 1 | P6: =IF(M6="","",ROUND(M6*IFERROR(INDEX(Weights!$B$2:$B$4,MATCH(G6,Weights!$A$2:$A$4,0)),0)*IFERROR(INDEX(Weights!$B$7:$B$11,MATCH(E6,Weights!$A$7:$A$11,0)),0)*IFERROR(INDEX(Weights!$B$14:$B$17,MATCH(TEXT(J6,"0"),Weights!$A$14:$A$17,0)),0)/(1+N(N6)/50),1)) | Q6: Y
A7: 6 | B7: google ads agency in mumbai | C7: Google Ads | D7: Service + city | E7: India | F7: Mumbai, Maharashtra, India | G7: Commercial | H7: Decision | I7: Google Ads spoke | J7: 1 | P7: =IF(M7="","",ROUND(M7*IFERROR(INDEX(Weights!$B$2:$B$4,MATCH(G7,Weights!$A$2:$A$4,0)),0)*IFERROR(INDEX(Weights!$B$7:$B$11,MATCH(E7,Weights!$A$7:$A$11,0)),0)*IFERROR(INDEX(Weights!$B$14:$B$17,MATCH(TEXT(J7,"0"),Weights!$A$14:$A$17,0)),0)/(1+N(N7)/50),1)) | Q7: Y
A8: 7 | B8: amazon marketing agency in mumbai | C8: Amazon Ads | D8: Service + city | E8: India | F8: Mumbai, Maharashtra, India | G8: Commercial | H8: Decision | I8: Amazon Ads spoke | J8: 1 | P8: =IF(M8="","",ROUND(M8*IFERROR(INDEX(Weights!$B$2:$B$4,MATCH(G8,Weights!$A$2:$A$4,0)),0)*IFERROR(INDEX(Weights!$B$7:$B$11,MATCH(E8,Weights!$A$7:$A$11,0)),0)*IFERROR(INDEX(Weights!$B$14:$B$17,MATCH(TEXT(J8,"0"),Weights!$A$14:$A$17,0)),0)/(1+N(N8)/50),1)) | Q8: Y
A9: 8 | B9: shopify developer in mumbai | C9: Shopify development | D9: Service + city | E9: India | F9: Mumbai, Maharashtra, India | G9: Commercial | H9: Decision | I9: Shopify page | J9: 1 | P9: =IF(M9="","",ROUND(M9*IFERROR(INDEX(Weights!$B$2:$B$4,MATCH(G9,Weights!$A$2:$A$4,0)),0)*IFERROR(INDEX(Weights!$B$7:$B$11,MATCH(E9,Weights!$A$7:$A$11,0)),0)*IFERROR(INDEX(Weights!$B$14:$B$17,MATCH(TEXT(J9,"0"),Weights!$A$14:$A$17,0)),0)/(1+N(N9)/50),1)) | Q9: Y
A10: 9 | B10: shopify development company in mumbai | C10: Shopify development | D10: Service + city | E10: India | F10: Mumbai, Maharashtra, India | G10: Commercial | H10: Decision | I10: Shopify page | J10: 1 | P10: =IF(M10="","",ROUND(M10*IFERROR(INDEX(Weights!$B$2:$B$4,MATCH(G10,Weights!$A$2:$A$4,0)),0)*IFERROR(INDEX(Weights!$B$7:$B$11,MATCH(E10,Weights!$A$7:$A$11,0)),0)*IFERROR(INDEX(Weights!$B$14:$B$17,MATCH(TEXT(J10,"0"),Weights!$A$14:$A$17,0)),0)/(1+N(N10)/50),1)) | Q10: Y
A11: 10 | B11: seo agency in mumbai | C11: SEO / AEO / GEO | D11: Service + city | E11: India | F11: Mumbai, Maharashtra, India | G11: Commercial | H11: Decision | I11: SEO page | J11: 2 | P11: =IF(M11="","",ROUND(M11*IFERROR(INDEX(Weights!$B$2:$B$4,MATCH(G11,Weights!$A$2:$A$4,0)),0)*IFERROR(INDEX(Weights!$B$7:$B$11,MATCH(E11,Weights!$A$7:$A$11,0)),0)*IFERROR(INDEX(Weights!$B$14:$B$17,MATCH(TEXT(J11,"0"),Weights!$A$14:$A$17,0)),0)/(1+N(N11)/50),1)) | Q11: Y
A12: 11 | B12: social media marketing agency in mumbai | C12: Performance creatives | D12: Service + city | E12: India | F12: Mumbai, Maharashtra, India | G12: Commercial | H12: Decision | I12: Performance creatives | J12: 2 | P12: =IF(M12="","",ROUND(M12*IFERROR(INDEX(Weights!$B$2:$B$4,MATCH(G12,Weights!$A$2:$A$4,0)),0)*IFERROR(INDEX(Weights!$B$7:$B$11,MATCH(E12,Weights!$A$7:$A$11,0)),0)*IFERROR(INDEX(Weights!$B$14:$B$17,MATCH(TEXT(J12,"0"),Weights!$A$14:$A$17,0)),0)/(1+N(N12)/50),1)) | Q12: Y
A13: 12 | B13: influencer marketing agency in mumbai | C13: Influencer marketing | D13: Service + city | E13: India | F13: Mumbai, Maharashtra, India | G13: Commercial | H13: Decision | I13: Influencer page | J13: 3 | P13: =IF(M13="","",ROUND(M13*IFERROR(INDEX(Weights!$B$2:$B$4,MATCH(G13,Weights!$A$2:$A$4,0)),0)*IFERROR(INDEX(Weights!$B$7:$B$11,MATCH(E13,Weights!$A$7:$A$11,0)),0)*IFERROR(INDEX(Weights!$B$14:$B$17,MATCH(TEXT(J13,"0"),Weights!$A$14:$A$17,0)),0)/(1+N(N13)/50),1)) | Q13: Y
... A56: 55 | B56: performance marketing agency in gurgaon | C56: Performance marketing | D56: Service + city | E56: India | F56: Gurugram, Haryana, India | G56: Commercial | H56: Decision | I56: Hub (national) / city section | J56: 1 | P56: =IF(M56="","",ROUND(M56*IFERROR(INDEX(Weights!$B$2:$B$4,MATCH(G56,Weights!$A$2:$A$4,0)),0)*IFERROR(INDEX(Weights!$B$7:$B$11,MATCH(E56,Weights!$A$7:$A$11,0)),0)*IFERROR(INDEX(Weights!$B$14:$B$17,MATCH(TEXT(J56,"0"),Weights!$A$14:$A$17,0)),0)/(1+N(N56)/50),1)) | Q56: Y
A57: 56 | B57: performance marketing agency in gurugram | C57: Performance marketing | D57: Service + city | E57: India | F57: Gurugram, Haryana, India | G57: Commercial | H57: Decision | I57: Hub (national) / city section | J57: 1 | K57: Spelling variant: same page as primary | P57: =IF(M57="","",ROUND(M57*IFERROR(INDEX(Weights!$B$2:$B$4,MATCH(G57,Weights!$A$2:$A$4,0)),0)*IFERROR(INDEX(Weights!$B$7:$B$11,MATCH(E57,Weights!$A$7:$A$11,0)),0)*IFERROR(INDEX(Weights!$B$14:$B$17,MATCH(TEXT(J57,"0"),Weights!$A$14:$A$17,0)),0)/(1+N(N57)/50),1)) | Q57: N
A58: 57 | B58: digital marketing agency for ecommerce in gurgaon | C58: Performance marketing | D58: Service + city | E58: India | F58: Gurugram, Haryana, India | G58: Commercial | H58: Decision | I58: Hub (national) | J58: 1 | P58: =IF(M58="","",ROUND(M58*IFERROR(INDEX(Weights!$B$2:$B$4,MATCH(G58,Weights!$A$2:$A$4,0)),0)*IFERROR(INDEX(Weights!$B$7:$B$11,MATCH(E58,Weights!$A$7:$A$11,0)),0)*IFERROR(INDEX(Weights!$B$14:$B$17,MATCH(TEXT(J58,"0"),Weights!$A$14:$A$17,0)),0)/(1+N(N58)/50),1)) | Q58: Y
A59: 58 | B59: digital marketing agency for ecommerce in gurugram | C59: Performance marketing | D59: Service + city | E59: India | F59: Gurugram, Haryana, India | G59: Commercial | H59: Decision | I59: Hub (national) | J59: 1 | K59: Spelling variant: same page as primary | P59: =IF(M59="","",ROUND(M59*IFERROR(INDEX(Weights!$B$2:$B$4,MATCH(G59,Weights!$A$2:$A$4,0)),0)*IFERROR(INDEX(Weights!$B$7:$B$11,MATCH(E59,Weights!$A$7:$A$11,0)),0)*IFERROR(INDEX(Weights!$B$14:$B$17,MATCH(TEXT(J59,"0"),Weights!$A$14:$A$17,0)),0)/(1+N(N59)/50),1)) | Q59: N
A60: 59 | B60: d2c marketing agency in gurgaon | C60: Performance marketing | D60: Service + city | E60: India | F60: Gurugram, Haryana, India | G60: Commercial | H60: Decision | I60: Hub (national) | J60: 1 | P60: =IF(M60="","",ROUND(M60*IFERROR(INDEX(Weights!$B$2:$B$4,MATCH(G60,Weights!$A$2:$A$4,0)),0)*IFERROR(INDEX(Weights!$B$7:$B$11,MATCH(E60,Weights!$A$7:$A$11,0)),0)*IFERROR(INDEX(Weights!$B$14:$B$17,MATCH(TEXT(J60,"0"),Weights!$A$14:$A$17,0)),0)/(1+N(N60)/50),1)) | Q60: Y
A61: 60 | B61: d2c marketing agency in gurugram | C61: Performance marketing | D61: Service + city | E61: India | F61: Gurugram, Haryana, India | G61: Commercial | H61: Decision | I61: Hub (national) | J61: 1 | K61: Spelling variant: same page as primary | P61: =IF(M61="","",ROUND(M61*IFERROR(INDEX(Weights!$B$2:$B$4,MATCH(G61,Weights!$A$2:$A$4,0)),0)*IFERROR(INDEX(Weights!$B$7:$B$11,MATCH(E61,Weights!$A$7:$A$11,0)),0)*IFERROR(INDEX(Weights!$B$14:$B$17,MATCH(TEXT(J61,"0"),Weights!$A$14:$A$17,0)),0)/(1+N(N61)/50),1)) | Q61: N
A62: 61 | B62: facebook ads agency in gurgaon | C62: Meta Ads | D62: Service + city | E62: India | F62: Gurugram, Haryana, India | G62: Commercial | H62: Decision | I62: Meta Ads spoke | J62: 1 | P62: =IF(M62="","",ROUND(M62*IFERROR(INDEX(Weights!$B$2:$B$4,MATCH(G62,Weights!$A$2:$A$4,0)),0)*IFERROR(INDEX(Weights!$B$7:$B$11,MATCH(E62,Weights!$A$7:$A$11,0)),0)*IFERROR(INDEX(Weights!$B$14:$B$17,MATCH(TEXT(J62,"0"),Weights!$A$14:$A$17,0)),0)/(1+N(N62)/50),1)) | Q62: Y
A63: 62 | B63: facebook ads agency in gurugram | C63: Meta Ads | D63: Service + city | E63: India | F63: Gurugram, Haryana, India | G63: Commercial | H63: Decision | I63: Meta Ads spoke | J63: 1 | K63: Spelling variant: same page as primary | P63: =IF(M63="","",ROUND(M63*IFERROR(INDEX(Weights!$B$2:$B$4,MATCH(G63,Weights!$A$2:$A$4,0)),0)*IFERROR(INDEX(Weights!$B$7:$B$11,MATCH(E63,Weights!$A$7:$A$11,0)),0)*IFERROR(INDEX(Weights!$B$14:$B$17,MATCH(TEXT(J63,"0"),Weights!$A$14:$A$17,0)),0)/(1+N(N63)/50),1)) | Q63: N
A64: 63 | B64: meta ads agency in gurgaon | C64: Meta Ads | D64: Service + city | E64: India | F64: Gurugram, Haryana, India | G64: Commercial | H64: Decision | I64: Meta Ads spoke | J64: 1 | P64: =IF(M64="","",ROUND(M64*IFERROR(INDEX(Weights!$B$2:$B$4,MATCH(G64,Weights!$A$2:$A$4,0)),0)*IFERROR(INDEX(Weights!$B$7:$B$11,MATCH(E64,Weights!$A$7:$A$11,0)),0)*IFERROR(INDEX(Weights!$B$14:$B$17,MATCH(TEXT(J64,"0"),Weights!$A$14:$A$17,0)),0)/(1+N(N64)/50),1)) | Q64: Y
A65: 64 | B65: meta ads agency in gurugram | C65: Meta Ads | D65: Service + city | E65: India | F65: Gurugram, Haryana, India | G65: Commercial | H65: Decision | I65: Meta Ads spoke | J65: 1 | K65: Spelling variant: same page as primary | P65: =IF(M65="","",ROUND(M65*IFERROR(INDEX(Weights!$B$2:$B$4,MATCH(G65,Weights!$A$2:$A$4,0)),0)*IFERROR(INDEX(Weights!$B$7:$B$11,MATCH(E65,Weights!$A$7:$A$11,0)),0)*IFERROR(INDEX(Weights!$B$14:$B$17,MATCH(TEXT(J65,"0"),Weights!$A$14:$A$17,0)),0)/(1+N(N65)/50),1)) | Q65: N
A66: 65 | B66: google ads agency in gurgaon | C66: Google Ads | D66: Service + city | E66: India | F66: Gurugram, Haryana, India | G66: Commercial | H66: Decision | I66: Google Ads spoke | J66: 1 | P66: =IF(M66="","",ROUND(M66*IFERROR(INDEX(Weights!$B$2:$B$4,MATCH(G66,Weights!$A$2:$A$4,0)),0)*IFERROR(INDEX(Weights!$B$7:$B$11,MATCH(E66,Weights!$A$7:$A$11,0)),0)*IFERROR(INDEX(Weights!$B$14:$B$17,MATCH(TEXT(J66,"0"),Weights!$A$14:$A$17,0)),0)/(1+N(N66)/50),1)) | Q66: Y
A67: 66 | B67: google ads agency in gurugram | C67: Google Ads | D67: Service + city | E67: India | F67: Gurugram, Haryana, India | G67: Commercial | H67: Decision | I67: Google Ads spoke | J67: 1 | K67: Spelling variant: same page as primary | P67: =IF(M67="","",ROUND(M67*IFERROR(INDEX(Weights!$B$2:$B$4,MATCH(G67,Weights!$A$2:$A$4,0)),0)*IFERROR(INDEX(Weights!$B$7:$B$11,MATCH(E67,Weights!$A$7:$A$11,0)),0)*IFERROR(INDEX(Weights!$B$14:$B$17,MATCH(TEXT(J67,"0"),Weights!$A$14:$A$17,0)),0)/(1+N(N67)/50),1)) | Q67: N
A68: 67 | B68: amazon marketing agency in gurgaon | C68: Amazon Ads | D68: Service + city | E68: India | F68: Gurugram, Haryana, India | G68: Commercial | H68: Decision | I68: Amazon Ads spoke | J68: 1 | P68: =IF(M68="","",ROUND(M68*IFERROR(INDEX(Weights!$B$2:$B$4,MATCH(G68,Weights!$A$2:$A$4,0)),0)*IFERROR(INDEX(Weights!$B$7:$B$11,MATCH(E68,Weights!$A$7:$A$11,0)),0)*IFERROR(INDEX(Weights!$B$14:$B$17,MATCH(TEXT(J68,"0"),Weights!$A$14:$A$17,0)),0)/(1+N(N68)/50),1)) | Q68: Y
A69: 68 | B69: amazon marketing agency in gurugram | C69: Amazon Ads | D69: Service + city | E69: India | F69: Gurugram, Haryana, India | G69: Commercial | H69: Decision | I69: Amazon Ads spoke | J69: 1 | K69: Spelling variant: same page as primary | P69: =IF(M69="","",ROUND(M69*IFERROR(INDEX(Weights!$B$2:$B$4,MATCH(G69,Weights!$A$2:$A$4,0)),0)*IFERROR(INDEX(Weights!$B$7:$B$11,MATCH(E69,Weights!$A$7:$A$11,0)),0)*IFERROR(INDEX(Weights!$B$14:$B$17,MATCH(TEXT(J69,"0"),Weights!$A$14:$A$17,0)),0)/(1+N(N69)/50),1)) | Q69: N
A70: 69 | B70: shopify developer in gurgaon | C70: Shopify development | D70: Service + city | E70: India | F70: Gurugram, Haryana, India | G70: Commercial | H70: Decision | I70: Shopify page | J70: 1 | P70: =IF(M70="","",ROUND(M70*IFERROR(INDEX(Weights!$B$2:$B$4,MATCH(G70,Weights!$A$2:$A$4,0)),0)*IFERROR(INDEX(Weights!$B$7:$B$11,MATCH(E70,Weights!$A$7:$A$11,0)),0)*IFERROR(INDEX(Weights!$B$14:$B$17,MATCH(TEXT(J70,"0"),Weights!$A$14:$A$17,0)),0)/(1+N(N70)/50),1)) | Q70: Y
A71: 70 | B71: shopify developer in gurugram | C71: Shopify development | D71: Service + city | E71: India | F71: Gurugram, Haryana, India | G71: Commercial | H71: Decision | I71: Shopify page | J71: 1 | K71: Spelling variant: same page as primary | P71: =IF(M71="","",ROUND(M71*IFERROR(INDEX(Weights!$B$2:$B$4,MATCH(G71,Weights!$A$2:$A$4,0)),0)*IFERROR(INDEX(Weights!$B$7:$B$11,MATCH(E71,Weights!$A$7:$A$11,0)),0)*IFERROR(INDEX(Weights!$B$14:$B$17,MATCH(TEXT(J71,"0"),Weights!$A$14:$A$17,0)),0)/(1+N(N71)/50),1)) | Q71: N
A72: 71 | B72: shopify development company in gurgaon | C72: Shopify development | D72: Service + city | E72: India | F72: Gurugram, Haryana, India | G72: Commercial | H72: Decision | I72: Shopify page | J72: 1 | P72: =IF(M72="","",ROUND(M72*IFERROR(INDEX(Weights!$B$2:$B$4,MATCH(G72,Weights!$A$2:$A$4,0)),0)*IFERROR(INDEX(Weights!$B$7:$B$11,MATCH(E72,Weights!$A$7:$A$11,0)),0)*IFERROR(INDEX(Weights!$B$14:$B$17,MATCH(TEXT(J72,"0"),Weights!$A$14:$A$17,0)),0)/(1+N(N72)/50),1)) | Q72: Y
A73: 72 | B73: shopify development company in gurugram | C73: Shopify development | D73: Service + city | E73: India | F73: Gurugram, Haryana, India | G73: Commercial | H73: Decision | I73: Shopify page | J73: 1 | K73: Spelling variant: same page as primary | P73: =IF(M73="","",ROUND(M73*IFERROR(INDEX(Weights!$B$2:$B$4,MATCH(G73,Weights!$A$2:$A$4,0)),0)*IFERROR(INDEX(Weights!$B$7:$B$11,MATCH(E73,Weights!$A$7:$A$11,0)),0)*IFERROR(INDEX(Weights!$B$14:$B$17,MATCH(TEXT(J73,"0"),Weights!$A$14:$A$17,0)),0)/(1+N(N73)/50),1)) | Q73: N
A74: 73 | B74: seo agency in gurgaon | C74: SEO / AEO / GEO | D74: Service + city | E74: India | F74: Gurugram, Haryana, India | G74: Commercial | H74: Decision | I74: SEO page | J74: 2 | P74: =IF(M74="","",ROUND(M74*IFERROR(INDEX(Weights!$B$2:$B$4,MATCH(G74,Weights!$A$2:$A$4,0)),0)*IFERROR(INDEX(Weights!$B$7:$B$11,MATCH(E74,Weights!$A$7:$A$11,0)),0)*IFERROR(INDEX(Weights!$B$14:$B$17,MATCH(TEXT(J74,"0"),Weights!$A$14:$A$17,0)),0)/(1+N(N74)/50),1)) | Q74: Y
A75: 74 | B75: seo agency in gurugram | C75: SEO / AEO / GEO | D75: Service + city | E75: India | F75: Gurugram, Haryana, India | G75: Commercial | H75: Decision | I75: SEO page | J75: 2 | K75: Spelling variant: same page as primary | P75: =IF(M75="","",ROUND(M75*IFERROR(INDEX(Weights!$B$2:$B$4,MATCH(G75,Weights!$A$2:$A$4,0)),0)*IFERROR(INDEX(Weights!$B$7:$B$11,MATCH(E75,Weights!$A$7:$A$11,0)),0)*IFERROR(INDEX(Weights!$B$14:$B$17,MATCH(TEXT(J75,"0"),Weights!$A$14:$A$17,0)),0)/(1+N(N75)/50),1)) | Q75: N
A76: 75 | B76: social media marketing agency in gurgaon | C76: Performance creatives | D76: Service + city | E76: India | F76: Gurugram, Haryana, India | G76: Commercial | H76: Decision | I76: Performance creatives | J76: 2 | P76: =IF(M76="","",ROUND(M76*IFERROR(INDEX(Weights!$B$2:$B$4,MATCH(G76,Weights!$A$2:$A$4,0)),0)*IFERROR(INDEX(Weights!$B$7:$B$11,MATCH(E76,Weights!$A$7:$A$11,0)),0)*IFERROR(INDEX(Weights!$B$14:$B$17,MATCH(TEXT(J76,"0"),Weights!$A$14:$A$17,0)),0)/(1+N(N76)/50),1)) | Q76: Y
A77: 76 | B77: social media marketing agency in gurugram | C77: Performance creatives | D77: Service + city | E77: India | F77: Gurugram, Haryana, India | G77: Commercial | H77: Decision | I77: Performance creatives | J77: 2 | K77: Spelling variant: same page as primary | P77: =IF(M77="","",ROUND(M77*IFERROR(INDEX(Weights!$B$2:$B$4,MATCH(G77,Weights!$A$2:$A$4,0)),0)*IFERROR(INDEX(Weights!$B$7:$B$11,MATCH(E77,Weights!$A$7:$A$11,0)),0)*IFERROR(INDEX(Weights!$B$14:$B$17,MATCH(TEXT(J77,"0"),Weights!$A$14:$A$17,0)),0)/(1+N(N77)/50),1)) | Q77: N
A78: 77 | B78: influencer marketing agency in gurgaon | C78: Influencer marketing | D78: Service + city | E78: India | F78: Gurugram, Haryana, India | G78: Commercial | H78: Decision | I78: Influencer page | J78: 3 | P78: =IF(M78="","",ROUND(M78*IFERROR(INDEX(Weights!$B$2:$B$4,MATCH(G78,Weights!$A$2:$A$4,0)),0)*IFERROR(INDEX(Weights!$B$7:$B$11,MATCH(E78,Weights!$A$7:$A$11,0)),0)*IFERROR(INDEX(Weights!$B$14:$B$17,MATCH(TEXT(J78,"0"),Weights!$A$14:$A$17,0)),0)/(1+N(N78)/50),1)) | Q78: Y
A79: 78 | B79: influencer marketing agency in gurugram | C79: Influencer marketing | D79: Service + city | E79: India | F79: Gurugram, Haryana, India | G79: Commercial | H79: Decision | I79: Influencer page | J79: 3 | K79: Spelling variant: same page as primary | P79: =IF(M79="","",ROUND(M79*IFERROR(INDEX(Weights!$B$2:$B$4,MATCH(G79,Weights!$A$2:$A$4,0)),0)*IFERROR(INDEX(Weights!$B$7:$B$11,MATCH(E79,Weights!$A$7:$A$11,0)),0)*IFERROR(INDEX(Weights!$B$14:$B$17,MATCH(TEXT(J79,"0"),Weights!$A$14:$A$17,0)),0)/(1+N(N79)/50),1)) | Q79: N
A80: 79 | B80: branding agency in gurgaon | C80: Branding / D2C launch | D80: Service + city | E80: India | F80: Gurugram, Haryana, India | G80: Commercial | H80: Decision | I80: D2C brand launch | J80: 3 | P80: =IF(M80="","",ROUND(M80*IFERROR(INDEX(Weights!$B$2:$B$4,MATCH(G80,Weights!$A$2:$A$4,0)),0)*IFERROR(INDEX(Weights!$B$7:$B$11,MATCH(E80,Weights!$A$7:$A$11,0)),0)*IFERROR(INDEX(Weights!$B$14:$B$17,MATCH(TEXT(J80,"0"),Weights!$A$14:$A$17,0)),0)/(1+N(N80)/50),1)) | Q80: Y
A81: 80 | B81: branding agency in gurugram | C81: Branding / D2C launch | D81: Service + city | E81: India | F81: Gurugram, Haryana, India | G81: Commercial | H81: Decision | I81: D2C brand launch | J81: 3 | K81: Spelling variant: same page as primary | P81: =IF(M81="","",ROUND(M81*IFERROR(INDEX(Weights!$B$2:$B$4,MATCH(G81,Weights!$A$2:$A$4,0)),0)*IFERROR(INDEX(Weights!$B$7:$B$11,MATCH(E81,Weights!$A$7:$A$11,0)),0)*IFERROR(INDEX(Weights!$B$14:$B$17,MATCH(TEXT(J81,"0"),Weights!$A$14:$A$17,0)),0)/(1+N(N81)/50),1)) | Q81: N
A82: 81 | B82: packaging design agency in gurgaon | C82: Branding / D2C launch | D82: Service + city | E82: India | F82: Gurugram, Haryana, India | G82: Commercial | H82: Decision | I82: D2C brand launch | J82: 3 | P82: =IF(M82="","",ROUND(M82*IFERROR(INDEX(Weights!$B$2:$B$4,MATCH(G82,Weights!$A$2:$A$4,0)),0)*IFERROR(INDEX(Weights!$B$7:$B$11,MATCH(E82,Weights!$A$7:$A$11,0)),0)*IFERROR(INDEX(Weights!$B$14:$B$17,MATCH(TEXT(J82,"0"),Weights!$A$14:$A$17,0)),0)/(1+N(N82)/50),1)) | Q82: Y
...

Sheet Summary
A1: Total Ahrefs/Semrush volume by service and market (fills automatically)
A3: Service | B3: India | C3: UAE | D3: United States | E3: Canada | F3: Australia | G3: Keywords listed | H3: Total Opportunity Score
A4: Performance marketing | B4: =SUMIFS(Keywords!$M$2:$M$1355,Keywords!$C$2:$C$1355,$A4,Keywords!$E$2:$E$1355,B$3,Keywords!$Q$2:$Q$1355,"Y") -> 0 | C4: =SUMIFS(Keywords!$M$2:$M$1355,Keywords!$C$2:$C$1355,$A4,Keywords!$E$2:$E$1355,C$3,Keywords!$Q$2:$Q$1355,"Y") -> 0 | D4: =SUMIFS(Keywords!$M$2:$M$1355,Keywords!$C$2:$C$1355,$A4,Keywords!$E$2:$E$1355,D$3,Keywords!$Q$2:$Q$1355,"Y") -> 0 | E4: =SUMIFS(Keywords!$M$2:$M$1355,Keywords!$C$2:$C$1355,$A4,Keywords!$E$2:$E$1355,E$3,Keywords!$Q$2:$Q$1355,"Y") -> 0 | F4: =SUMIFS(Keywords!$M$2:$M$1355,Keywords!$C$2:$C$1355,$A4,Keywords!$E$2:$E$1355,F$3,Keywords!$Q$2:$Q$1355,"Y") -> 0 | G4: =COUNTIF(Keywords!$C$2:$C$1355,$A4) -> 213 | H4: =SUMIFS(Keywords!$P$2:$P$1355,Keywords!$C$2:$C$1355,$A4,Keywords!$Q$2:$Q$1355,"Y") -> 0
A5: Meta Ads | B5: =SUMIFS(Keywords!$M$2:$M$1355,Keywords!$C$2:$C$1355,$A5,Keywords!$E$2:$E$1355,B$3,Keywords!$Q$2:$Q$1355,"Y") -> 0 | C5: =SUMIFS(Keywords!$M$2:$M$1355,Keywords!$C$2:$C$1355,$A5,Keywords!$E$2:$E$1355,C$3,Keywords!$Q$2:$Q$1355,"Y") -> 0 | D5: =SUMIFS(Keywords!$M$2:$M$1355,Keywords!$C$2:$C$1355,$A5,Keywords!$E$2:$E$1355,D$3,Keywords!$Q$2:$Q$1355,"Y") -> 0 | E5: =SUMIFS(Keywords!$M$2:$M$1355,Keywords!$C$2:$C$1355,$A5,Keywords!$E$2:$E$1355,E$3,Keywords!$Q$2:$Q$1355,"Y") -> 0 | F5: =SUMIFS(Keywords!$M$2:$M$1355,Keywords!$C$2:$C$1355,$A5,Keywords!$E$2:$E$1355,F$3,Keywords!$Q$2:$Q$1355,"Y") -> 0 | G5: =COUNTIF(Keywords!$C$2:$C$1355,$A5) -> 183 | H5: =SUMIFS(Keywords!$P$2:$P$1355,Keywords!$C$2:$C$1355,$A5,Keywords!$Q$2:$Q$1355,"Y") -> 0
A6: Google Ads | B6: =SUMIFS(Keywords!$M$2:$M$1355,Keywords!$C$2:$C$1355,$A6,Keywords!$E$2:$E$1355,B$3,Keywords!$Q$2:$Q$1355,"Y") -> 0 | C6: =SUMIFS(Keywords!$M$2:$M$1355,Keywords!$C$2:$C$1355,$A6,Keywords!$E$2:$E$1355,C$3,Keywords!$Q$2:$Q$1355,"Y") -> 0 | D6: =SUMIFS(Keywords!$M$2:$M$1355,Keywords!$C$2:$C$1355,$A6,Keywords!$E$2:$E$1355,D$3,Keywords!$Q$2:$Q$1355,"Y") -> 0 | E6: =SUMIFS(Keywords!$M$2:$M$1355,Keywords!$C$2:$C$1355,$A6,Keywords!$E$2:$E$1355,E$3,Keywords!$Q$2:$Q$1355,"Y") -> 0 | F6: =SUMIFS(Keywords!$M$2:$M$1355,Keywords!$C$2:$C$1355,$A6,Keywords!$E$2:$E$1355,F$3,Keywords!$Q$2:$Q$1355,"Y") -> 0 | G6: =COUNTIF(Keywords!$C$2:$C$1355,$A6) -> 116 | H6: =SUMIFS(Keywords!$P$2:$P$1355,Keywords!$C$2:$C$1355,$A6,Keywords!$Q$2:$Q$1355,"Y") -> 0
A7: Amazon Ads | B7: =SUMIFS(Keywords!$M$2:$M$1355,Keywords!$C$2:$C$1355,$A7,Keywords!$E$2:$E$1355,B$3,Keywords!$Q$2:$Q$1355,"Y") -> 0 | C7: =SUMIFS(Keywords!$M$2:$M$1355,Keywords!$C$2:$C$1355,$A7,Keywords!$E$2:$E$1355,C$3,Keywords!$Q$2:$Q$1355,"Y") -> 0 | D7: =SUMIFS(Keywords!$M$2:$M$1355,Keywords!$C$2:$C$1355,$A7,Keywords!$E$2:$E$1355,D$3,Keywords!$Q$2:$Q$1355,"Y") -> 0 | E7: =SUMIFS(Keywords!$M$2:$M$1355,Keywords!$C$2:$C$1355,$A7,Keywords!$E$2:$E$1355,E$3,Keywords!$Q$2:$Q$1355,"Y") -> 0 | F7: =SUMIFS(Keywords!$M$2:$M$1355,Keywords!$C$2:$C$1355,$A7,Keywords!$E$2:$E$1355,F$3,Keywords!$Q$2:$Q$1355,"Y") -> 0 | G7: =COUNTIF(Keywords!$C$2:$C$1355,$A7) -> 90 | H7: =SUMIFS(Keywords!$P$2:$P$1355,Keywords!$C$2:$C$1355,$A7,Keywords!$Q$2:$Q$1355,"Y") -> 0
A8: Quick commerce ads | B8: =SUMIFS(Keywords!$M$2:$M$1355,Keywords!$C$2:$C$1355,$A8,Keywords!$E$2:$E$1355,B$3,Keywords!$Q$2:$Q$1355,"Y") -> 0 | C8: =SUMIFS(Keywords!$M$2:$M$1355,Keywords!$C$2:$C$1355,$A8,Keywords!$E$2:$E$1355,C$3,Keywords!$Q$2:$Q$1355,"Y") -> 0 | D8: =SUMIFS(Keywords!$M$2:$M$1355,Keywords!$C$2:$C$1355,$A8,Keywords!$E$2:$E$1355,D$3,Keywords!$Q$2:$Q$1355,"Y") -> 0 | E8: =SUMIFS(Keywords!$M$2:$M$1355,Keywords!$C$2:$C$1355,$A8,Keywords!$E$2:$E$1355,E$3,Keywords!$Q$2:$Q$1355,"Y") -> 0 | F8: =SUMIFS(Keywords!$M$2:$M$1355,Keywords!$C$2:$C$1355,$A8,Keywords!$E$2:$E$1355,F$3,Keywords!$Q$2:$Q$1355,"Y") -> 0 | G8: =COUNTIF(Keywords!$C$2:$C$1355,$A8) -> 18 | H8: =SUMIFS(Keywords!$P$2:$P$1355,Keywords!$C$2:$C$1355,$A8,Keywords!$Q$2:$Q$1355,"Y") -> 0
A9: Shopify development | B9: =SUMIFS(Keywords!$M$2:$M$1355,Keywords!$C$2:$C$1355,$A9,Keywords!$E$2:$E$1355,B$3,Keywords!$Q$2:$Q$1355,"Y") -> 0 | C9: =SUMIFS(Keywords!$M$2:$M$1355,Keywords!$C$2:$C$1355,$A9,Keywords!$E$2:$E$1355,C$3,Keywords!$Q$2:$Q$1355,"Y") -> 0 | D9: =SUMIFS(Keywords!$M$2:$M$1355,Keywords!$C$2:$C$1355,$A9,Keywords!$E$2:$E$1355,D$3,Keywords!$Q$2:$Q$1355,"Y") -> 0 | E9: =SUMIFS(Keywords!$M$2:$M$1355,Keywords!$C$2:$C$1355,$A9,Keywords!$E$2:$E$1355,E$3,Keywords!$Q$2:$Q$1355,"Y") -> 0 | F9: =SUMIFS(Keywords!$M$2:$M$1355,Keywords!$C$2:$C$1355,$A9,Keywords!$E$2:$E$1355,F$3,Keywords!$Q$2:$Q$1355,"Y") -> 0 | G9: =COUNTIF(Keywords!$C$2:$C$1355,$A9) -> 152 | H9: =SUMIFS(Keywords!$P$2:$P$1355,Keywords!$C$2:$C$1355,$A9,Keywords!$Q$2:$Q$1355,"Y") -> 0
A10: CRO | B10: =SUMIFS(Keywords!$M$2:$M$1355,Keywords!$C$2:$C$1355,$A10,Keywords!$E$2:$E$1355,B$3,Keywords!$Q$2:$Q$1355,"Y") -> 0 | C10: =SUMIFS(Keywords!$M$2:$M$1355,Keywords!$C$2:$C$1355,$A10,Keywords!$E$2:$E$1355,C$3,Keywords!$Q$2:$Q$1355,"Y") -> 0 | D10: =SUMIFS(Keywords!$M$2:$M$1355,Keywords!$C$2:$C$1355,$A10,Keywords!$E$2:$E$1355,D$3,Keywords!$Q$2:$Q$1355,"Y") -> 0 | E10: =SUMIFS(Keywords!$M$2:$M$1355,Keywords!$C$2:$C$1355,$A10,Keywords!$E$2:$E$1355,E$3,Keywords!$Q$2:$Q$1355,"Y") -> 0 | F10: =SUMIFS(Keywords!$M$2:$M$1355,Keywords!$C$2:$C$1355,$A10,Keywords!$E$2:$E$1355,F$3,Keywords!$Q$2:$Q$1355,"Y") -> 0 | G10: =COUNTIF(Keywords!$C$2:$C$1355,$A10) -> 73 | H10: =SUMIFS(Keywords!$P$2:$P$1355,Keywords!$C$2:$C$1355,$A10,Keywords!$Q$2:$Q$1355,"Y") -> 0
A11: Retention marketing | B11: =SUMIFS(Keywords!$M$2:$M$1355,Keywords!$C$2:$C$1355,$A11,Keywords!$E$2:$E$1355,B$3,Keywords!$Q$2:$Q$1355,"Y") -> 0 | C11: =SUMIFS(Keywords!$M$2:$M$1355,Keywords!$C$2:$C$1355,$A11,Keywords!$E$2:$E$1355,C$3,Keywords!$Q$2:$Q$1355,"Y") -> 0 | D11: =SUMIFS(Keywords!$M$2:$M$1355,Keywords!$C$2:$C$1355,$A11,Keywords!$E$2:$E$1355,D$3,Keywords!$Q$2:$Q$1355,"Y") -> 0 | E11: =SUMIFS(Keywords!$M$2:$M$1355,Keywords!$C$2:$C$1355,$A11,Keywords!$E$2:$E$1355,E$3,Keywords!$Q$2:$Q$1355,"Y") -> 0 | F11: =SUMIFS(Keywords!$M$2:$M$1355,Keywords!$C$2:$C$1355,$A11,Keywords!$E$2:$E$1355,F$3,Keywords!$Q$2:$Q$1355,"Y") -> 0 | G11: =COUNTIF(Keywords!$C$2:$C$1355,$A11) -> 100 | H11: =SUMIFS(Keywords!$P$2:$P$1355,Keywords!$C$2:$C$1355,$A11,Keywords!$Q$2:$Q$1355,"Y") -> 0
A12: Performance creatives | B12: =SUMIFS(Keywords!$M$2:$M$1355,Keywords!$C$2:$C$1355,$A12,Keywords!$E$2:$E$1355,B$3,Keywords!$Q$2:$Q$1355,"Y") -> 0 | C12: =SUMIFS(Keywords!$M$2:$M$1355,Keywords!$C$2:$C$1355,$A12,Keywords!$E$2:$E$1355,C$3,Keywords!$Q$2:$Q$1355,"Y") -> 0 | D12: =SUMIFS(Keywords!$M$2:$M$1355,Keywords!$C$2:$C$1355,$A12,Keywords!$E$2:$E$1355,D$3,Keywords!$Q$2:$Q$1355,"Y") -> 0 | E12: =SUMIFS(Keywords!$M$2:$M$1355,Keywords!$C$2:$C$1355,$A12,Keywords!$E$2:$E$1355,E$3,Keywords!$Q$2:$Q$1355,"Y") -> 0 | F12: =SUMIFS(Keywords!$M$2:$M$1355,Keywords!$C$2:$C$1355,$A12,Keywords!$E$2:$E$1355,F$3,Keywords!$Q$2:$Q$1355,"Y") -> 0 | G12: =COUNTIF(Keywords!$C$2:$C$1355,$A12) -> 113 | H12: =SUMIFS(Keywords!$P$2:$P$1355,Keywords!$C$2:$C$1355,$A12,Keywords!$Q$2:$Q$1355,"Y") -> 0
A13: SEO / AEO / GEO | B13: =SUMIFS(Keywords!$M$2:$M$1355,Keywords!$C$2:$C$1355,$A13,Keywords!$E$2:$E$1355,B$3,Keywords!$Q$2:$Q$1355,"Y") -> 0 | C13: =SUMIFS(Keywords!$M$2:$M$1355,Keywords!$C$2:$C$1355,$A13,Keywords!$E$2:$E$1355,C$3,Keywords!$Q$2:$Q$1355,"Y") -> 0 | D13: =SUMIFS(Keywords!$M$2:$M$1355,Keywords!$C$2:$C$1355,$A13,Keywords!$E$2:$E$1355,D$3,Keywords!$Q$2:$Q$1355,"Y") -> 0 | E13: =SUMIFS(Keywords!$M$2:$M$1355,Keywords!$C$2:$C$1355,$A13,Keywords!$E$2:$E$1355,E$3,Keywords!$Q$2:$Q$1355,"Y") -> 0 | F13: =SUMIFS(Keywords!$M$2:$M$1355,Keywords!$C$2:$C$1355,$A13,Keywords!$E$2:$E$1355,F$3,Keywords!$Q$2:$Q$1355,"Y") -> 0 | G13: =COUNTIF(Keywords!$C$2:$C$1355,$A13) -> 59 | H13: =SUMIFS(Keywords!$P$2:$P$1355,Keywords!$C$2:$C$1355,$A13,Keywords!$Q$2:$Q$1355,"Y") -> 0
A14: Influencer marketing | B14: =SUMIFS(Keywords!$M$2:$M$1355,Keywords!$C$2:$C$1355,$A14,Keywords!$E$2:$E$1355,B$3,Keywords!$Q$2:$Q$1355,"Y") -> 0 | C14: =SUMIFS(Keywords!$M$2:$M$1355,Keywords!$C$2:$C$1355,$A14,Keywords!$E$2:$E$1355,C$3,Keywords!$Q$2:$Q$1355,"Y") -> 0 | D14: =SUMIFS(Keywords!$M$2:$M$1355,Keywords!$C$2:$C$1355,$A14,Keywords!$E$2:$E$1355,D$3,Keywords!$Q$2:$Q$1355,"Y") -> 0 | E14: =SUMIFS(Keywords!$M$2:$M$1355,Keywords!$C$2:$C$1355,$A14,Keywords!$E$2:$E$1355,E$3,Keywords!$Q$2:$Q$1355,"Y") -> 0 | F14: =SUMIFS(Keywords!$M$2:$M$1355,Keywords!$C$2:$C$1355,$A14,Keywords!$E$2:$E$1355,F$3,Keywords!$Q$2:$Q$1355,"Y") -> 0 | G14: =COUNTIF(Keywords!$C$2:$C$1355,$A14) -> 49 | H14: =SUMIFS(Keywords!$P$2:$P$1355,Keywords!$C$2:$C$1355,$A14,Keywords!$Q$2:$Q$1355,"Y") -> 0
A15: Branding / D2C launch | B15: =SUMIFS(Keywords!$M$2:$M$1355,Keywords!$C$2:$C$1355,$A15,Keywords!$E$2:$E$1355,B$3,Keywords!$Q$2:$Q$1355,"Y") -> 0 | C15: =SUMIFS(Keywords!$M$2:$M$1355,Keywords!$C$2:$C$1355,$A15,Keywords!$E$2:$E$1355,C$3,Keywords!$Q$2:$Q$1355,"Y") -> 0 | D15: =SUMIFS(Keywords!$M$2:$M$1355,Keywords!$C$2:$C$1355,$A15,Keywords!$E$2:$E$1355,D$3,Keywords!$Q$2:$Q$1355,"Y") -> 0 | E15: =SUMIFS(Keywords!$M$2:$M$1355,Keywords!$C$2:$C$1355,$A15,Keywords!$E$2:$E$1355,E$3,Keywords!$Q$2:$Q$1355,"Y") -> 0 | F15: =SUMIFS(Keywords!$M$2:$M$1355,Keywords!$C$2:$C$1355,$A15,Keywords!$E$2:$E$1355,F$3,Keywords!$Q$2:$Q$1355,"Y") -> 0 | G15: =COUNTIF(Keywords!$C$2:$C$1355,$A15) -> 68 | H15: =SUMIFS(Keywords!$P$2:$P$1355,Keywords!$C$2:$C$1355,$A15,Keywords!$Q$2:$Q$1355,"Y") -> 0
... A25: Branded | B25: =SUMIFS(Keywords!$M$2:$M$1355,Keywords!$C$2:$C$1355,$A25,Keywords!$E$2:$E$1355,B$3,Keywords!$Q$2:$Q$1355,"Y") -> 0 | C25: =SUMIFS(Keywords!$M$2:$M$1355,Keywords!$C$2:$C$1355,$A25,Keywords!$E$2:$E$1355,C$3,Keywords!$Q$2:$Q$1355,"Y") -> 0 | D25: =SUMIFS(Keywords!$M$2:$M$1355,Keywords!$C$2:$C$1355,$A25,Keywords!$E$2:$E$1355,D$3,Keywords!$Q$2:$Q$1355,"Y") -> 0 | E25: =SUMIFS(Keywords!$M$2:$M$1355,Keywords!$C$2:$C$1355,$A25,Keywords!$E$2:$E$1355,E$3,Keywords!$Q$2:$Q$1355,"Y") -> 0 | F25: =SUMIFS(Keywords!$M$2:$M$1355,Keywords!$C$2:$C$1355,$A25,Keywords!$E$2:$E$1355,F$3,Keywords!$Q$2:$Q$1355,"Y") -> 0 | G25: =COUNTIF(Keywords!$C$2:$C$1355,$A25) -> 5 | H25: =SUMIFS(Keywords!$P$2:$P$1355,Keywords!$C$2:$C$1355,$A25,Keywords!$Q$2:$Q$1355,"Y") -> 0
A26: Total | B26: =SUM(B4:B25) -> 0 | C26: =SUM(C4:C25) -> 0 | D26: =SUM(D4:D25) -> 0 | E26: =SUM(E4:E25) -> 0 | F26: =SUM(F4:F25) -> 0 | G26: =SUM(G4:G25) -> 1354 | H26: =SUM(H4:H25) -> 0
A29: India city keyword volume (fills automatically)
A30: GKP Location | B30: Volume | C30: Keywords
A31: Mumbai, Maharashtra, India | B31: =SUMIFS(Keywords!$M$2:$M$1355,Keywords!$F$2:$F$1355,$A31,Keywords!$Q$2:$Q$1355,"Y") -> 0 | C31: =COUNTIF(Keywords!$F$2:$F$1355,$A31) -> 18
A32: Thane, Maharashtra, India | B32: =SUMIFS(Keywords!$M$2:$M$1355,Keywords!$F$2:$F$1355,$A32,Keywords!$Q$2:$Q$1355,"Y") -> 0 | C32: =COUNTIF(Keywords!$F$2:$F$1355,$A32) -> 18
A33: Delhi, India | B33: =SUMIFS(Keywords!$M$2:$M$1355,Keywords!$F$2:$F$1355,$A33,Keywords!$Q$2:$Q$1355,"Y") -> 0 | C33: =COUNTIF(Keywords!$F$2:$F$1355,$A33) -> 18
A34: Gurugram, Haryana, India | B34: =SUMIFS(Keywords!$M$2:$M$1355,Keywords!$F$2:$F$1355,$A34,Keywords!$Q$2:$Q$1355,"Y") -> 0 | C34: =COUNTIF(Keywords!$F$2:$F$1355,$A34) -> 36
A35: Noida, Uttar Pradesh, India | B35: =SUMIFS(Keywords!$M$2:$M$1355,Keywords!$F$2:$F$1355,$A35,Keywords!$Q$2:$Q$1355,"Y") -> 0 | C35: =COUNTIF(Keywords!$F$2:$F$1355,$A35) -> 18
A36: Bengaluru, Karnataka, India | B36: =SUMIFS(Keywords!$M$2:$M$1355,Keywords!$F$2:$F$1355,$A36,Keywords!$Q$2:$Q$1355,"Y") -> 0 | C36: =COUNTIF(Keywords!$F$2:$F$1355,$A36) -> 36
A37: Hyderabad, Telangana, India | B37: =SUMIFS(Keywords!$M$2:$M$1355,Keywords!$F$2:$F$1355,$A37,Keywords!$Q$2:$Q$1355,"Y") -> 0 | C37: =COUNTIF(Keywords!$F$2:$F$1355,$A37) -> 18
A38: Pune, Maharashtra, India | B38: =SUMIFS(Keywords!$M$2:$M$1355,Keywords!$F$2:$F$1355,$A38,Keywords!$Q$2:$Q$1355,"Y") -> 0 | C38: =COUNTIF(Keywords!$F$2:$F$1355,$A38) -> 18
A39: Chennai, Tamil Nadu, India | B39: =SUMIFS(Keywords!$M$2:$M$1355,Keywords!$F$2:$F$1355,$A39,Keywords!$Q$2:$Q$1355,"Y") -> 0 | C39: =COUNTIF(Keywords!$F$2:$F$1355,$A39) -> 18
A40: Indore, Madhya Pradesh, India | B40: =SUMIFS(Keywords!$M$2:$M$1355,Keywords!$F$2:$F$1355,$A40,Keywords!$Q$2:$Q$1355,"Y") -> 0 | C40: =COUNTIF(Keywords!$F$2:$F$1355,$A40) -> 18
A41: Ahmedabad, Gujarat, India | B41: =SUMIFS(Keywords!$M$2:$M$1355,Keywords!$F$2:$F$1355,$A41,Keywords!$Q$2:$Q$1355,"Y") -> 0 | C41: =COUNTIF(Keywords!$F$2:$F$1355,$A41) -> 18
A42: Jaipur, Rajasthan, India | B42: =SUMIFS(Keywords!$M$2:$M$1355,Keywords!$F$2:$F$1355,$A42,Keywords!$Q$2:$Q$1355,"Y") -> 0 | C42: =COUNTIF(Keywords!$F$2:$F$1355,$A42) -> 18
... A45: Surat, Gujarat, India | B45: =SUMIFS(Keywords!$M$2:$M$1355,Keywords!$F$2:$F$1355,$A45,Keywords!$Q$2:$Q$1355,"Y") -> 0 | C45: =COUNTIF(Keywords!$F$2:$F$1355,$A45) -> 18

Sheet City Intelligence
A1: Market | B1: City / Region | C1: GKP Location | D1: Keywords in sheet | E1: Volume (auto) | F1: Why it matters (evidence or inference) | G1: Main risk | H1: Recommended approach | I1: Priority | J1: Confidence
A2: UAE | B2: Dubai | C2: Dubai, United Arab Emirates | D2: =COUNTIF(Keywords!$F$2:$F$1355,C2) -> 52 | E2: =SUMIFS(Keywords!$M$2:$M$1355,Keywords!$F$2:$F$1355,C2,Keywords!$Q$2:$Q$1355,"Y") -> 0 | F2: Core of UAE D2C, marketplaces (Amazon.ae, Noon, Namshi) and agency buying. Published Meta agency fees AED 8K to 22K a month, 2.5 to 7x MMC's India ticket (upGrowth, 2026). | G2: Crowded local agency market; buyers expect local presence and Arabic creative. Do not claim a Dubai office. | H2: One UAE growth page + GCC Q-com page + corridor outreach to Indian brands on Amazon.ae and Noon | I2: Validate (90-day test) | J2: Medium
A3: UAE | B3: Abu Dhabi | C3: Abu Dhabi, United Arab Emirates | D3: =COUNTIF(Keywords!$F$2:$F$1355,C3) -> 26 | E3: =SUMIFS(Keywords!$M$2:$M$1355,Keywords!$F$2:$F$1355,C3,Keywords!$Q$2:$Q$1355,"Y") -> 0 | F3: Government and enterprise heavy; fewer D2C founders than Dubai (inference). | G3: Buying skews to large tenders and government vendors. | H3: Covered by UAE page; no separate page | I3: Later | J3: Low
A4: UAE | B4: Sharjah | C4: Sharjah, United Arab Emirates | D4: =COUNTIF(Keywords!$F$2:$F$1355,C4) -> 26 | E4: =SUMIFS(Keywords!$M$2:$M$1355,Keywords!$F$2:$F$1355,C4,Keywords!$Q$2:$Q$1355,"Y") -> 0 | F4: Lower-cost base for small traders and some ecommerce operators (inference). | G4: Lower budgets; overlaps Dubai metro. | H4: Covered by Dubai/UAE page | I4: Deprioritise | J4: Low
A5: UAE | B5: UAE (national) | C5: United Arab Emirates | D5: =COUNTIF(Keywords!$F$2:$F$1355,C5) -> 44 | E5: =SUMIFS(Keywords!$M$2:$M$1355,Keywords!$F$2:$F$1355,C5,Keywords!$Q$2:$Q$1355,"Y") -> 0 | F5: Ecommerce estimated AED 45.1B in 2026 (businessdubai.ae). Quick commerce players: Talabat Mart, Noon Minutes, Careem Quik. | G5: Small Shopify base (about 12K stores) caps organic volume. | H5: GCC quick commerce guide is the clearest unclaimed angle | I5: Validate | J5: Medium
A6: United States | B6: New York | C6: New York, New York, United States | D6: =COUNTIF(Keywords!$F$2:$F$1355,C6) -> 25 | E6: =SUMIFS(Keywords!$M$2:$M$1355,Keywords!$F$2:$F$1355,C6,Keywords!$Q$2:$Q$1355,"Y") -> 0 | F6: Largest concentration of DTC brands and consumer-brand buyers; DTC stores cluster in NYC (Retail Dive). | G6: Most competitive agency SERPs in the world; local agencies dominate. | H6: Monitor only. Reach via white label to NYC agencies | I6: Deprioritise (direct) | J6: Medium
A7: United States | B7: Los Angeles | C7: Los Angeles, California, United States | D7: =COUNTIF(Keywords!$F$2:$F$1355,C7) -> 25 | E7: =SUMIFS(Keywords!$M$2:$M$1355,Keywords!$F$2:$F$1355,C7,Keywords!$Q$2:$Q$1355,"Y") -> 0 | F7: Fashion, beauty, lifestyle and creator-led DTC hub (Printful, mean.ceo 2026). | G7: Same as NYC; creative-heavy expectations. | H7: Monitor only; UGC white label angle | I7: Deprioritise (direct) | J7: Medium
A8: United States | B8: San Francisco Bay Area | C8: San Francisco-Oakland-San Jose CA (DMA), United States | D8: =COUNTIF(Keywords!$F$2:$F$1355,C8) -> 25 | E8: =SUMIFS(Keywords!$M$2:$M$1355,Keywords!$F$2:$F$1355,C8,Keywords!$Q$2:$Q$1355,"Y") -> 0 | F8: Top startup ecosystem; large Indian-founder population (inference). | G8: Tech-first, not D2C-first; very high CAC to win. | H8: Founder network / referral, not SEO | I8: Deprioritise | J8: Low
A9: United States | B9: Austin | C9: Austin, Texas, United States | D9: =COUNTIF(Keywords!$F$2:$F$1355,C9) -> 25 | E9: =SUMIFS(Keywords!$M$2:$M$1355,Keywords!$F$2:$F$1355,C9,Keywords!$Q$2:$Q$1355,"Y") -> 0 | F9: Emerging DTC and beauty hub; South Congress called DTC Row (Glossy). | G9: Small agency market; local relationships matter. | H9: Monitor | I9: Deprioritise | J9: Low
A10: United States | B10: Miami | C10: Miami, Florida, United States | D10: =COUNTIF(Keywords!$F$2:$F$1355,C10) -> 25 | E10: =SUMIFS(Keywords!$M$2:$M$1355,Keywords!$F$2:$F$1355,C10,Keywords!$Q$2:$Q$1355,"Y") -> 0 | F10: Digital-first and Hispanic-market brands (Printful). | G10: Spanish-language creative demand. | H10: Monitor | I10: Deprioritise | J10: Low
A11: United States | B11: Dallas / Houston | C11: Dallas, Texas / Houston, Texas, United States | D11: =COUNTIF(Keywords!$F$2:$F$1355,C11) -> 0 | E11: =SUMIFS(Keywords!$M$2:$M$1355,Keywords!$F$2:$F$1355,C11,Keywords!$Q$2:$Q$1355,"Y") -> 0 | F11: Mid-size DTC growth markets; sizeable Indian diaspora business communities (inference). | G11: No proof base. | H11: Diaspora founder outreach test only | I11: Deprioritise | J11: Low
A12: United States | B12: New Jersey | C12: New Jersey, United States | D12: =COUNTIF(Keywords!$F$2:$F$1355,C12) -> 25 | E12: =SUMIFS(Keywords!$M$2:$M$1355,Keywords!$F$2:$F$1355,C12,Keywords!$Q$2:$Q$1355,"Y") -> 0 | F12: Dense Indian-American business community (Edison, Jersey City) and NYC metro brands (inference). | G12: Small-business budgets in diaspora segment. | H12: Possible corridor test for Indian-origin food/ethnic brands | I12: Later | J12: Low
A13: United States | B13: Chicago / Seattle / Boston / Denver | C13: Respective cities | D13: =COUNTIF(Keywords!$F$2:$F$1355,C13) -> 0 | E13: =SUMIFS(Keywords!$M$2:$M$1355,Keywords!$F$2:$F$1355,C13,Keywords!$Q$2:$Q$1355,"Y") -> 0 | F13: Secondary ecommerce hubs; Boston and Chicago show up for DTC retail (Retail Dive). | G13: No differentiator for MMC. | H13: Monitor | I13: Deprioritise | J13: Low
... A21: Australia | B21: Perth / Adelaide | C21: Respective cities | D21: =COUNTIF(Keywords!$F$2:$F$1355,C21) -> 0 | E21: =SUMIFS(Keywords!$M$2:$M$1355,Keywords!$F$2:$F$1355,C21,Keywords!$Q$2:$Q$1355,"Y") -> 0 | F21: Small markets; Perth is IST+2.5h, the best overlap (fact). | G21: Low volume. | H21: Monitor | I21: Deprioritise | J21: Low
A23: Grouped rows (e.g. Dallas / Houston) show 0 in the auto columns; filter the Keywords sheet by each city's GKP Location instead.

Sheet Exclusions
A1: Term or pattern | B1: Why exclude | C1: Use as | D1: Applies to
A2: jobs, salary, internship, interview questions, resume | B2: Job seekers, not buyers | C2: Organic: ignore. Paid: negative keyword | D2: All services
A3: course, certification, syllabus, exam | B3: Learners, not buyers | C3: Organic: ignore. Paid: negative | D3: All services
A4: free template, download, cracked | B4: No purchase intent | C4: Paid: negative | D4: All services
A5: buy lead database, contact list, telecalling jobs, appointment setter | B5: Outbound or data buyers; MMC sells inbound | C5: Paid: negative unless scope changes | D5: B2B lead generation
A6: ugc creator jobs, become a ugc creator, modelling auditions | B6: Creators looking for work | C6: Paid: negative | D6: UGC / creatives
A7: whatsapp bulk sender software | B7: Wants a tool, not managed service | C7: Paid: negative (contextual) | D7: Retention
A8: school admission near me, college application form | B8: Parents and students, not institutions | C8: Paid: negative | D8: Education
A9: monday.com, monday crm, monday marketing templates | B9: Brand collision with monday.com SaaS | C9: Always use full name 'Monday Marketing Company'; paid: negative on monday.com terms | D9: Branded
A10: pricing, cost, affordable | B10: NOT excluded: often purchase intent | C10: Keep. Qualify on the page instead | D10: All services

Sheet Weights
A1: Intent weight
A2: Commercial | B2: 1 | C2: Ready to hire
A3: Investigation | B3: 0.7 | C3: Comparing agencies or prices
A4: Informational | B4: 0.25 | C4: Learning; feeds AEO/GEO and retargeting
A6: Market weight
A7: India | B7: 1 | C7: Core market, proof exists
A8: UAE | B8: 1.3 | C8: Higher fees (AED 8K to 22K retainers); test market
A9: United States | B9: 0.3 | C9: Direct winning unlikely; white label only
A10: Canada | B10: 0.2 | C10: Deprioritised
A11: Australia | B11: 0.2 | C11: Deprioritised
A13: Priority weight
A14: 1 | B14: 1 | C14: Build first
A15: 2 | B15: 0.6 | C15: Build after proof
A16: 3 | B16: 0.3 | C16: Low effort
A17: 4 | B17: 0.05 | C17: Monitor only
A19: Weights are judgement calls by the strategist, not data. Change the yellow cells and every score recalculates.
